<?xml version="1.0"?>
<robot xmlns:xacro="http://www.ros.org/wiki/xacro" name="stretch_main">

  <xacro:property name="joint_damping" value="200"/>
  <xacro:property name="arm_damping" value="200"/>
  <xacro:property name="joint_friction" value="10"/>
  <xacro:property name="arm_friction" value="20"/>
  <xacro:property name="joint_spring_stiffness" value="0"/>
  <xacro:property name="joint_spring_reference" value="0"/>

  <link
    name="base_link">
    <inertial>
      <origin
        xyz="-0.109461304328163 -0.000741018909047708 0.0914915269429946"
        rpy="0 0 0" />
      <mass
        value="16.0" />
      <inertia
        ixx="0.00013"
        ixy="0"
        ixz="0"
        iyy="0.00012"
        iyz="0"
        izz="0.000218" />
    </inertial>
    <visual>
      <origin
        xyz="0 0 0"
        rpy="0 0 0" />
      <geometry>
        <mesh
          filename="package://stretch_description/meshes/base_link.STL" />
      </geometry>
      <material
        name="LightGray">
        <color
          rgba=".74 .74 .78 1" />
      </material>
    </visual>
    <collision>
      <origin
        xyz="0 0 0"
        rpy="0 0 0" />
      <geometry>
        <mesh
          filename="package://stretch_description/meshes/collision/base_link.STL" />
      </geometry>
    </collision>
  </link>

  <link
    name="link_right_wheel">
    <inertial>
      <origin
        xyz="0 0 0.0239581106165018"
        rpy="0 0 0" />
      <mass
        value="0.01" />
      <inertia
        ixx="0.001"
        ixy="0"
        ixz="0"
        iyy="0.001"
        iyz="0"
        izz="0.001" />
    </inertial>
    <visual>
      <origin
        xyz="0 0 0"
        rpy="0 0 0" />
      <geometry>
        <mesh
          filename="package://stretch_description/meshes/link_right_wheel.STL" />
      </geometry>
      <material
        name="">
        <color
          rgba=".13 .13 .13 1" />
      </material>
    </visual>
    <collision>
      <origin
        xyz="0 0 0"
        rpy="0 0 0" />
      <geometry>
          <cylinder radius="0.051" length="0.0225" />
      </geometry>
    </collision>
  </link>

  <joint
    name="joint_right_wheel"
    type="continuous">
    <origin
      xyz="-0.00300000000000034 -0.15765 0.0508000000000004"
      rpy="-${pi/2} 0 0 " />
    <parent
      link="base_link" />
    <child
      link="link_right_wheel" />
    <axis
      xyz="0 0 1" />
    <dynamics damping="${joint_damping}" friction="${joint_friction}" spring_reference="${joint_spring_reference}" spring_stiffness="{joint_spring_stiffness}"/>
  </joint>

  <link
    name="link_left_wheel">
    <inertial>
      <origin
        xyz="0 0 -0.0239581106165035"
        rpy="0 0 0" />
      <mass
        value="0.01" />
      <inertia
        ixx="0.001"
        ixy="0"
        ixz="0"
        iyy="0.001"
        iyz="0"
        izz="0.001" />
    </inertial>
    <visual>
      <origin
        xyz="0 0 0"
        rpy="0 0 0" />
      <geometry>
        <mesh
          filename="package://stretch_description/meshes/link_left_wheel.STL" />
      </geometry>
      <material
        name="">
        <color
          rgba=".13 .13 .13 1" />
      </material>
    </visual>
    <collision>
      <origin
        xyz="0 0 0"
        rpy="0 0 0" />
      <geometry>
          <cylinder radius="0.051" length="0.0225" />
      </geometry>
    </collision>
  </link>

  <joint
    name="joint_left_wheel"
    type="continuous">
    <origin
      xyz="-0.00300000000001899 0.15765 0.0507999999999994"
      rpy="-1.5707963267949 0 0" />
    <parent
      link="base_link" />
    <child
      link="link_left_wheel" />
    <axis
      xyz="0 0 1" />
    <dynamics damping="${joint_damping}" friction="${joint_friction}" spring_reference="${joint_spring_reference}" spring_stiffness="{joint_spring_stiffness}"/>
  </joint>

  <link name="caster_link">
    <collision>
      <geometry>
        <sphere radius="0.032"/>
      </geometry>
      <origin rpy="0 0 0" xyz="0 0 0"/>
      <surface>
        <friction>
          <ode>
            <mu>0</mu>
            <mu2>0</mu2>
            <slip1>1.0</slip1>
            <slip2>1.0</slip2>
          </ode>
        </friction>
      </surface>
    </collision>
    <visual>
      <origin
        xyz="0 0 0"
        rpy="0 0 0" />
      <geometry>
        <mesh
          filename="package://stretch_description/meshes/omni_wheel_m.STL" />
      </geometry>
      <material
        name="">
        <color
          rgba=".13 .13 .13 1" />
      </material>
    </visual>
    <inertial>
      <mass value="0.01" />
      <origin xyz="0 0 0" />
      <inertia
        ixx="0.001"
        ixy="0"
        ixz="0"
        iyy="0.001"
        iyz="0"
        izz="0.001" />
    </inertial>
  </link>

  <joint name="caster_joint" type="fixed">
    <parent link="base_link"/>
    <child link="caster_link"/>
    <origin xyz="-0.245 0.0 0.032" rpy="${-pi/2} 0 0"/>
    <axis xyz="0 0 1" />
  </joint>

  <link
    name="link_mast">
    <inertial>
      <origin
        xyz="0 0.7073971284176834 0"
        rpy="0 0 0" />
      <mass
        value="3" />
      <inertia
        ixx="0.000251"
        ixy="0"
        ixz="-0"
        iyy="0.000000"
        iyz="0"
        izz="0.000251" />
    </inertial>
    <visual>
      <origin
        xyz="0 0 0"
        rpy="0 0 0" />
      <geometry>
        <mesh
          filename="package://stretch_description/meshes/link_mast.STL" />
      </geometry>
      <material
        name="">
        <color
          rgba=".13 .13 .13 1" />
      </material>
    </visual>
    <collision>
      <origin
        xyz="0 0.7075 0"
        rpy="0 0 0" />
      <geometry>
        <box size="0.0384 1.2850 0.0384" />
      </geometry>
    </collision>
  </link>

  <joint
    name="joint_mast"
    type="fixed">
    <origin
      xyz="-0.07 0.134999999999998 0.0284000000000001"
      rpy="1.5707963267949 0 0.00925318926571245" />
    <parent
      link="base_link" />
    <child
      link="link_mast" />
    <axis
      xyz="0 0 0" />
  </joint>

  <link
    name="link_lift">
    <inertial>
      <origin
        xyz="-0.0547636346252869 0.0380939689802074 0.00933159404448308"
        rpy="0 0 0" />
      <mass
        value="0.5" />
      <inertia
        ixx="0.000567192946271367"
        ixy="-0.00024607534789508"
        ixz="-0.000128108442260574"
        iyy="0.00127108364478659"
        iyz="7.61916855070339E-06"
        izz="0.00137296635099006" />
    </inertial>
    <visual>
      <origin
        xyz="0 0 0"
        rpy="0 0 0" />
      <geometry>
        <mesh
          filename="package://stretch_description/meshes/link_lift.STL" />
      </geometry>
      <material
        name="">
        <color
          rgba=".5 .5 .5 1" />
      </material>
    </visual>
    <collision>
      <origin
        xyz="0 0 0"
        rpy="0 0 0" />
      <geometry>
        <mesh
          filename="package://stretch_description/meshes/collision/link_lift.STL" />
      </geometry>
    </collision>
  </link>

  <joint
    name="joint_lift"
    type="prismatic">
    <origin
      xyz="-0.0369217062323472 0.165471199999996 -0.000341653286793524"
      rpy="-${pi/2} ${pi/2} 0" />
    <parent
      link="link_mast" />
    <child
      link="link_lift" />
    <axis
	xyz="0 0 1" />
  <!-- for now: hand copied range_m: from lift: from ~/repos/stretch_fleet/stretch-re1-1001/stretch_re1_factory_params.yaml -->
  <!--<limit effort="100" lower="0.0" upper="1.095" velocity="1.0"/>-->
  <!-- copied value did not reach the top of mesh model with GUI sliders and RViz -->
  <limit effort="100" lower="0.0" upper="1.1" velocity="0.3"/>
  <dynamics friction="40.0" damping="200.0"/>
  </joint>

  <link
    name="link_arm_l4">
    <inertial>
      <origin
        xyz="0 0 -0.0953252706040035"
        rpy="0 0 0" />
      <mass
        value="0.07" />
      <inertia
        ixx="0.000122002023066796"
        ixy="7.29593356230121E-13"
        ixz="9.63170353371061E-09"
        iyy="0.000122002023127152"
        iyz="-9.24154949889042E-09"
        izz="1.46043439809638E-12" />
    </inertial>
    <visual>
      <origin
        xyz="0 0 0"
        rpy="0 0 0" />
      <geometry>
        <mesh
          filename="package://stretch_description/meshes/link_arm_l4.STL" />
      </geometry>
      <material
        name="">
        <color
          rgba=".13 .13 .13 1" />
      </material>
    </visual>
    <collision>
      <origin
        xyz="0 0 -0.1112"
        rpy="0 0 0" />
      <geometry>
        <box size="0.0593 0.0592 0.2225" />
      </geometry>
    </collision>
  </link>

  <joint
    name="joint_arm_l4"
    type="fixed">
    <origin
      xyz="-0.25471 0 0"
      rpy="${pi/2} 0 -${pi/2}" />
    <parent
      link="link_lift" />
    <child
      link="link_arm_l4" />
    <axis
      xyz="0 0 0" />
    <dynamics damping="${arm_damping}" friction="${arm_friction}" />

  </joint>

  <link
    name="link_arm_l3">
    <inertial>
      <origin
        xyz="0 0 -0.0974069598289041"
        rpy="0 0 0" />
      <mass
        value="0.07" />
      <inertia
        ixx="0.001"
        ixy="0"
        ixz="0"
        iyy="0.001"
        iyz="0"
        izz="0.001" />
    </inertial>
    <visual>
      <origin
        xyz="0 0 0"
        rpy="0 0 0" />
      <geometry>
        <mesh
          filename="package://stretch_description/meshes/link_arm_l3.STL" />
      </geometry>
      <material
        name="">
        <color
          rgba=".13 .13 .13 1" />
      </material>
    </visual>
    <collision>
      <origin
        xyz="0 0 -0.1133"
        rpy="0 0 0" />
      <geometry>
        <box size="0.0552 0.0552 0.2265" />
      </geometry>
    </collision>
  </link>

  <joint
    name="joint_arm_l3"
    type="prismatic">
    <origin
      xyz="0 0 0.013"
      rpy="0 0 0" />
    <parent
      link="link_arm_l4" />
    <child
      link="link_arm_l3" />
    <axis
	xyz="0 0 1" />
    <!-- 0.13 = 0.52/4-->
    <limit effort="100" lower="0.0" upper="0.13" velocity="0.1"/>
    <dynamics damping="${arm_damping}" friction="${arm_friction}" />
  </joint>

  <link
    name="link_arm_l2">
    <inertial>
      <origin
        xyz="0 0 -0.097255883541891"
        rpy="0 0 0" />
      <mass
        value="0.06" />
      <inertia
        ixx="0.001"
        ixy="0"
        ixz="0"
        iyy="0.001"
        iyz="0"
        izz="0.001" />
    </inertial>
    <visual>
      <origin
        xyz="0 0 0"
        rpy="0 0 0" />
      <geometry>
        <mesh
          filename="package://stretch_description/meshes/link_arm_l2.STL" />
      </geometry>
      <material
        name="">
        <color
          rgba=".13 .13 .13 1" />
      </material>
    </visual>
    <collision>
      <origin
        xyz="0 0 -0.1133"
        rpy="0 0 0" />
      <geometry>
        <box size="0.0512 0.0512 0.2265" />
      </geometry>
    </collision>
  </link>

  <joint
    name="joint_arm_l2"
    type="prismatic">
    <origin
      xyz="0 0 0.013"
      rpy="0 0 0" />
    <parent
      link="link_arm_l3" />
    <child
      link="link_arm_l2" />
    <axis
	xyz="0 0 1" />
    <!-- 0.13 = 0.52/4-->
    <limit effort="100" lower="0.0" upper="0.13" velocity="0.1"/>
    <dynamics damping="${arm_damping}" friction="${arm_friction}" />
  </joint>

  <link
    name="link_arm_l1">
    <inertial>
      <origin
        xyz="0 0 -0.0969117032232756"
        rpy="0 0 0" />
      <mass
        value="0.05" />
      <inertia
        ixx="0.001"
        ixy="0"
        ixz="0"
        iyy="0.001"
        iyz="0"
        izz="0.001" />
    </inertial>
    <visual>
      <origin
        xyz="0 0 0"
        rpy="0 0 0" />
      <geometry>
        <mesh
          filename="package://stretch_description/meshes/link_arm_l1.STL" />
      </geometry>
      <material
        name="">
        <color
          rgba=".13 .13 .13 1" />
      </material>
    </visual>
    <collision>
      <origin
        xyz="0 0 -0.1133"
        rpy="0 0 0" />
      <geometry>
        <box size="0.0473 0.0472 0.2265"/>
      </geometry>
    </collision>
  </link>

  <joint
    name="joint_arm_l1"
    type="prismatic">
    <origin
      xyz="0 0 0.013"
      rpy="0 0 0" />
    <parent
      link="link_arm_l2" />
    <child
      link="link_arm_l1" />
    <axis
	xyz="0 0 1" />
    <!-- 0.13 = 0.52/4-->
    <limit effort="100" lower="0.0" upper="0.13" velocity="0.1"/>
    <dynamics damping="${arm_damping}" friction="${arm_friction}" />
  </joint>

  <link
    name="link_arm_l0">
    <inertial>
      <origin
        xyz="0.0230715049668191 -0.00195115833662818 -0.0360646347160285"
        rpy="0 0 0" />
      <mass
        value="0.10" />
      <inertia
        ixx="0.001"
        ixy="0"
        ixz="0"
        iyy="0.001"
        iyz="0"
        izz="0.001" />
    </inertial>
    <visual>
      <origin
        xyz="0 0 0"
        rpy="0 0 0" />
      <geometry>
        <mesh
          filename="package://stretch_description/meshes/link_arm_l0.STL" />
      </geometry>
      <material
        name="">
        <color
          rgba=".13 .13 .13 1" />
      </material>
    </visual>
    <collision>
      <origin
        xyz="0 0 0"
        rpy="0 0 0" />
      <geometry>
        <mesh
          filename="package://stretch_description/meshes/collision/link_arm_l0.STL" />
      </geometry>
    </collision>
    <collision>
      <origin
        xyz="0.0002 -0.0003 -0.0865"
        rpy="0 0 0" />
      <geometry>
        <box size="0.0457 0.0452 0.2265" />
      </geometry>
    </collision>
  </link>

  <joint
    name="joint_arm_l0"
    type="prismatic">
    <origin
      xyz="0 0 -0.0137499999999938"
      rpy="0 0 0" />
    <parent
      link="link_arm_l1" />
    <child
      link="link_arm_l0" />
    <axis
	xyz="0 0 1" />
    <!-- 0.13 = 0.52/4-->
    <limit effort="100" lower="0.0" upper="0.13" velocity="0.1"/>
    <dynamics damping="${arm_damping}" friction="${arm_friction}" />
  </joint>

  <link
    name="link_wrist_yaw">
    <inertial>
      <origin
        xyz="0 0 0.018946700595851"
        rpy="0 0 0" />
      <mass
        value="0.08" />
      <inertia
        ixx="0.001"
        ixy="0"
        ixz="0"
        iyy="0.001"
        iyz="0"
        izz="0.001" />
    </inertial>
    <visual>
      <origin
        xyz="0 0 0"
        rpy="0 0 0" />
      <geometry>
        <mesh
          filename="package://stretch_description/meshes/link_wrist_yaw.STL" />
      </geometry>
      <material
        name="">
        <color
	        rgba=".13 .13 .13 1" />
      </material>
    </visual>
    <collision>
      <origin
        xyz="0 0 0"
        rpy="0 0 0" />
      <geometry>
        <cylinder radius="0.015" length="0.0380" />
      </geometry>
    </collision>
  </link>

  <joint
    name="joint_wrist_yaw"
    type="revolute">
    <origin
      xyz="0.083 -0.03075 0"
      rpy="${pi/2} 0 0" />
    <parent
      link="link_arm_l0" />
    <child
      link="link_wrist_yaw" />
    <axis
      xyz="0 0 -1" />
    <!--
      stowed to front ~225 deg: 3.15159 x 1.25 = 3.9395
      using 4.0
      stowed to back ~100 deg:  100 / 180 x 3.14159 = 1.7453
      using -1.75
    -->
    <limit effort="100" lower="-1.75" upper="4.0" velocity="0.3"/>
  </joint>

  <link
    name="link_head">
    <inertial>
      <origin
        xyz="0.0372933550588956 0.045509432985552 0.0281136801213409"
        rpy="0 0 0" />
      <mass
        value="0.13" />
      <inertia
        ixx="0.001"
        ixy="0"
        ixz="0"
        iyy="0.001"
        iyz="0"
        izz="0.001" />
    </inertial>
    <visual>
      <origin
        xyz="0 0 0"
        rpy="0 0 0" />
      <geometry>
        <mesh
          filename="package://stretch_description/meshes/link_head.STL" />
      </geometry>
      <material
        name="">
        <color
          rgba=".5 .5 .5 1" />
      </material>
    </visual>
    <collision>
      <origin
        xyz="0 0 0"
        rpy="0 0 0" />
      <geometry>
        <mesh
          filename="package://stretch_description/meshes/collision/link_head.STL" />
      </geometry>
    </collision>
  </link>

  <joint
    name="joint_head"
    type="fixed">
    <origin
      xyz="0 1.33 0"
      rpy="${pi/2} -${pi/2} ${pi}" />
    <parent
      link="link_mast" />
    <child
      link="link_head" />
    <axis
      xyz="0 0 0" />
  </joint>

  <link
    name="link_head_pan">
    <inertial>
      <origin
        xyz="-0.00116200255310878 0.0130365621706306 0.00137629842298681"
        rpy="0 0 0" />
      <mass
        value="0.04" />
      <inertia
        ixx="0.001"
        ixy="0"
        ixz="0"
        iyy="0.001"
        iyz="0"
        izz="0.001" />
    </inertial>
    <visual>
      <origin
        xyz="0 0 0"
        rpy="0 0 0" />
      <geometry>
        <mesh
          filename="package://stretch_description/meshes/link_head_pan.STL" />
      </geometry>
      <material
        name="">
        <color
          rgba=".5 .5 .5 1" />
      </material>
    </visual>
    <collision>
      <origin
        xyz="0 0 0"
        rpy="0 0 0" />
      <geometry>
        <mesh
          filename="package://stretch_description/meshes/collision/link_head_pan.STL" />
      </geometry>
    </collision>
  </link>

  <joint
    name="joint_head_pan"
    type="revolute">
    <origin
      xyz="0.135 0.0731 -0.003"
      rpy="0 0 ${pi/2}" />
    <parent
      link="link_head" />
    <child
      link="link_head_pan" />
    <axis
	xyz="0 0 1" />
    <!-- unconstrained range for now -->
    <limit effort="100" lower="-3.9" upper="1.5" velocity="1.0"/>
  </joint>

  <link
    name="link_head_tilt">
    <inertial>
      <origin
        xyz="0.00920211049011871 -0.0279724762416447 0.0306580436227023"
        rpy="0 0 0" />
      <mass
        value="0.07" />
      <inertia
        ixx="0.001"
        ixy="0"
        ixz="0"
        iyy="0.001"
        iyz="0"
        izz="0.001" />
    </inertial>
    <visual>
      <origin
        xyz="0 0 0"
        rpy="0 0 0" />
      <geometry>
        <mesh
          filename="package://stretch_description/meshes/link_head_tilt.STL" />
      </geometry>
      <material
        name="">
        <color
          rgba=".74 .74 .78 1" />
      </material>
    </visual>
    <collision>
      <origin
        xyz="0 0 0"
        rpy="0 0 0" />
      <geometry>
        <mesh
          filename="package://stretch_description/meshes/collision/link_head_tilt.STL" />
      </geometry>
    </collision>
  </link>

  <joint
    name="joint_head_tilt"
    type="revolute">
    <origin
      xyz="-0.0013 0.027507 -0.053311"
      rpy="${pi/2} 0 0" />
    <parent
      link="link_head_pan" />
    <child
      link="link_head_tilt" />
    <axis
      xyz="0 0 1" />
    <!-- unconstrained range for now -->
    <limit effort="100" lower="-1.53" upper="0.79" velocity="1.0"/>
  </joint>

</robot>
