<?xml version="1.0"?>
<robot xmlns:xacro="http://www.ros.org/wiki/xacro" name="stretch_dex_wrist">

  <xacro:property name="scale_finger_length" value="0.9" />

  <link
    name="link_wrist_yaw_bottom">
    <inertial>
      <origin
        xyz="-0.012839101377342 -0.0382787718640742 -0.0228400332263617"
        rpy="0 0 0" />
      <mass
        value="0.0988906816399982" />
      <inertia
        ixx="2.60067866573596E-05"
        ixy="-6.73176267521354E-06"
        ixz="-2.43476436723672E-06"
        iyy="5.99482946819923E-06"
        iyz="-3.39642410492401E-06"
        izz="2.56907114334732E-05" />
    </inertial>
    <visual>
      <origin
        xyz="0 0 0"
        rpy="0 0 0" />
      <geometry>
        <mesh
          filename="package://stretch_description/meshes/dexwrist/link_wrist_yaw_bottom.STL" />
      </geometry>
      <material
        name="">
        <color
          rgba="0.13 0.13 0.13 1" />
      </material>
    </visual>
    <collision>
      <origin
        xyz="-0.0133 -0.0414 -0.0208"
        rpy="0 0 0" />
      <geometry>
        <box size="0.0629 0.0542 0.0415" />
      </geometry>
    </collision>
    <collision>
      <origin
        xyz="0.0005 -0.0146 -0.0042"
        rpy="0 0 0" />
      <geometry>
        <box size="0.0304 0.0807 0.0083" />
      </geometry>
    </collision>
    <collision>
      <origin
        xyz="0 0.0203 -0.0195"
        rpy="0 0 0" />
      <geometry>
        <box size="0.0295 0.0109 0.039" />
      </geometry>
    </collision>
  </link>
  <joint
    name="joint_wrist_yaw_bottom"
    type="fixed">
    <origin
      xyz="0 0 0"
      rpy="-${pi} 0 ${pi/2}" />
    <parent
      link="link_wrist_yaw" />
    <child
      link="link_wrist_yaw_bottom" />
    <axis
      xyz="0 0 0" />
  </joint>
  <link
    name="link_wrist_pitch">
    <inertial>
      <origin
        xyz="-0.00310609611067142 -0.0150777141465843 0.0204734587925901"
        rpy="0 0 0" />
      <mass
        value="0.0701267146295583" />
      <inertia
        ixx="2.55965614980905E-06"
        ixy="-1.47551515167608E-06"
        ixz="-6.31436085977252E-08"
        iyy="3.43968637386282E-06"
        iyz="-4.17813567208843E-07"
        izz="4.53568668211393E-06" />
    </inertial>
    <visual>
      <origin
        xyz="0 0 0"
        rpy="0 0 0" />
      <geometry>
        <mesh
          filename="package://stretch_description/meshes/dexwrist/link_wrist_pitch.STL" />
      </geometry>
      <material
        name="">
        <color
          rgba="0.13 0.13 0.13 1" />
      </material>
    </visual>
    <collision>
      <origin
        xyz="0 0 0"
        rpy="0 0 0" />
      <geometry>
        <mesh
          filename="package://stretch_description/meshes/dexwrist/collision/link_wrist_pitch.STL" />
      </geometry>
    </collision>
  </link>
  <joint
    name="joint_wrist_pitch"
    type="revolute">
    <origin
      xyz="0 -0.0195500000000002 -0.0247499999999984"
      rpy="${pi/2} 0 -${pi}" />
    <parent
      link="link_wrist_yaw_bottom" />
    <child
      link="link_wrist_pitch" />
    <axis
      xyz="0 0 -1" />
    <limit effort="100" lower="-${pi/2}" upper="0.56" velocity="1.0"/>
  </joint>
  <link
    name="link_wrist_roll">
    <inertial>
      <origin
        xyz="0 0 0.00768048802649798"
        rpy="0 0 0" />
      <mass
        value="0.00585666394358811" />
      <inertia
        ixx="5.61461154156397E-02"
        ixy="8.29518962984231E-07"
        ixz="-2.41382921888194E-06"
        iyy="1.11504692003467E-02"
        iyz="9.76174898123369E-07"
        izz="6.63803357903882E-02" />
    </inertial>
    <visual>
      <origin
        xyz="0 0 0"
        rpy="0 0 0" />
      <geometry>
        <mesh
          filename="package://stretch_description/meshes/dexwrist/link_wrist_roll.STL" />
      </geometry>
      <material
        name="">
        <color
          rgba="0.13 0.13 0.13 1" />
      </material>
    </visual>
    <collision>
      <origin
        xyz="0 0 0.0077"
        rpy="0 0 0" />
      <geometry>
        <cylinder radius="0.0145" length="0.0155" />
      </geometry>
    </collision>
  </link>
  <joint
    name="joint_wrist_roll"
    type="revolute">
    <origin
      xyz="-0.0188587444076125 -0.0239999999998942 0.01955"
      rpy="${pi} ${pi/2} 0" />
    <parent
      link="link_wrist_pitch" />
    <child
      link="link_wrist_roll" />
    <axis
      xyz="0 0 1" />
    <limit effort="100" lower="-${pi}" upper="${pi}" velocity="1.0"/>
  </joint>
  <link
    name="link_straight_gripper">
    <inertial>
      <origin
        xyz="0.00150764845432383 -0.00711581846201287 0.0399737901417758"
        rpy="0 0 0" />
      <mass
        value="0.0496384234458284" />
      <inertia
        ixx="5.61461154156397E-02"
        ixy="8.29518962984231E-07"
        ixz="-2.41382921888194E-06"
        iyy="1.11504692003467E-02"
        iyz="9.76174898123369E-07"
        izz="6.63803357903882E-02" />
    </inertial>
    <visual>
      <origin
        xyz="0 0 0"
        rpy="0 0 0" />
      <geometry>
        <mesh
          filename="package://stretch_description/meshes/dexwrist/link_straight_gripper.STL" />
      </geometry>
      <material
        name="">
        <color
          rgba="0.13 0.13 0.13 1" />
      </material>
    </visual>
    <collision>
      <origin
        xyz="0 -0.0143 0.0280"
        rpy="0 0 0" />
      <geometry>
        <box size="0.0496 0.0556 0.0560" />
      </geometry>
    </collision>
    <collision>
      <origin
        xyz="0 0 0.0759"
        rpy="0 0 0" />
      <geometry>
        <box size="0.0432 0.0292 0.0648" />
      </geometry>
    </collision>
  </link>
  <joint
    name="joint_straight_gripper"
    type="fixed">
    <origin
      xyz="0 0 0.0155"
      rpy="0 0 -${pi}" />
    <parent
      link="link_wrist_roll" />
    <child
      link="link_straight_gripper" />
    <axis
      xyz="0 0 0" />
  </joint>
  <link
    name="link_gripper_finger_right">
    <inertial>
      <origin
        xyz="-0.094981 -0.0080152 0"
        rpy="0 0 0" />
      <mass
        value="0.047621" />
      <inertia
        ixx="5.61461154156397E-02"
        ixy="8.29518962984231E-07"
        ixz="-2.41382921888194E-06"
        iyy="1.11504692003467E-02"
        iyz="9.76174898123369E-07"
        izz="6.63803357903882E-02" />
    </inertial>
    <visual>
      <origin
        xyz="0 0 0"
        rpy="0 0 0" />
      <geometry>
        <mesh
          filename="package://stretch_description/meshes/link_gripper_finger_right.STL" />
      </geometry>
      <material
        name="">
        <color
          rgba=".8 .8 .8 1" />
      </material>
    </visual>
    <collision>
      <origin
        xyz="0 0 0"
        rpy="0 0 0" />
      <geometry>
        <mesh
          filename="package://stretch_description/meshes/link_gripper_finger_right.STL" />
      </geometry>
    </collision>
  </link>
  <joint
    name="joint_gripper_finger_right"
    type="revolute">
    <origin
      xyz="-0.018599 0.003 0.033689"
      rpy="${pi/2} ${pi/2} 0" />
    <parent
      link="link_straight_gripper" />
    <child
      link="link_gripper_finger_right" />
    <axis
      xyz="0 0 1" />
    <limit effort="100" lower="-0.6" upper="0.6" velocity="1.0"/>
  </joint>
  <link
    name="link_gripper_fingertip_right">
    <inertial>
      <origin
        xyz="2.83785970833783E-08 6.75131661687089E-09 0.00812578923434215"
        rpy="0 0 0" />
      <mass
        value="0.00382160881468841" />
      <inertia
        ixx="5.61461154156397E-02"
        ixy="8.29518962984231E-07"
        ixz="-2.41382921888194E-06"
        iyy="1.11504692003467E-02"
        iyz="9.76174898123369E-07"
        izz="6.63803357903882E-02" />
    </inertial>
    <visual>
      <origin
        xyz="0 0 0"
        rpy="0 0 0" />
      <geometry>
        <mesh
          filename="package://stretch_description/meshes/link_gripper_fingertip.STL" />
      </geometry>
      <material
        name="">
        <color
          rgba=".25 .25 .25 1" />
      </material>
    </visual>
    <collision>
      <origin
        xyz="0 0 0"
        rpy="0 0 0" />
      <geometry>
        <mesh
          filename="package://stretch_description/meshes/collision/link_gripper_fingertip.STL" />
      </geometry>
    </collision>
  </link>
  <joint
    name="joint_gripper_fingertip_right"
    type="fixed">
    <origin
      xyz="-0.190596948563868 -0.015 0"
      rpy="-${pi/2} 0 0.540456056432235" />
    <parent
      link="link_gripper_finger_right" />
    <child
      link="link_gripper_fingertip_right" />
    <axis
      xyz="0 0 0" />
  </joint>
  <link
    name="link_gripper_finger_left">
    <inertial>
      <origin
        xyz="0.0949811095686165 -0.00801522758203194 1.38777878078145E-15"
        rpy="0 0 0" />
      <mass
        value="0.0476207785199479" />
      <inertia
        ixx="5.61461154156397E-02"
        ixy="8.29518962984231E-07"
        ixz="-2.41382921888194E-06"
        iyy="1.11504692003467E-02"
        iyz="9.76174898123369E-07"
        izz="6.63803357903882E-02" />
    </inertial>
    <visual>
      <origin
        xyz="0 0 0"
        rpy="${pi} 0 0" />
      <geometry>
        <mesh
          filename="package://stretch_description/meshes/link_gripper_finger_left.STL" />
      </geometry>
      <material
        name="">
        <color
          rgba=".8 .8 .8 1" />
      </material>
    </visual>
    <collision>
      <origin
        xyz="0 0 0"
        rpy="${pi} 0 0" />
      <geometry>
        <mesh
          filename="package://stretch_description/meshes/link_gripper_finger_left.STL" />
      </geometry>
    </collision>
  </link>
  <joint
    name="joint_gripper_finger_left"
    type="revolute">
    <origin
      xyz="0.018599 0.003 0.033689"
      rpy="${pi/2} -${pi/2} 0" />
    <parent
      link="link_straight_gripper" />
    <child
      link="link_gripper_finger_left" />
    <axis
      xyz="0 0 -1" />
    <limit effort="100" lower="-0.6" upper="0.6" velocity="1.0"/>
  </joint>
  <link
    name="link_gripper_fingertip_left">
    <inertial>
      <origin
        xyz="0 0 0.00812579036862837"
        rpy="0 0 0" />
      <mass
        value="0.00382160686584851" />
      <inertia
        ixx="5.61461154156397E-02"
        ixy="8.29518962984231E-07"
        ixz="-2.41382921888194E-06"
        iyy="1.11504692003467E-02"
        iyz="9.76174898123369E-07"
        izz="6.63803357903882E-02" />
    </inertial>
    <visual>
      <origin
        xyz="0 0 0"
        rpy="0 0 0" />
      <geometry>
        <mesh
          filename="package://stretch_description/meshes/link_gripper_fingertip.STL" />
      </geometry>
      <material
        name="">
        <color
          rgba=".25 .25 .25 1" />
      </material>
    </visual>
    <collision>
      <origin
        xyz="0 0 0"
        rpy="0 0 0" />
      <geometry>
        <mesh
          filename="package://stretch_description/meshes/collision/link_gripper_fingertip.STL" />
      </geometry>
    </collision>
  </link>
  <joint
    name="joint_gripper_fingertip_left"
    type="fixed">
    <origin
      xyz="0.190596948563868 -0.015 0"
      rpy="${pi/2} 0 2.60113659715756" />
    <parent
      link="link_gripper_finger_left" />
    <child
      link="link_gripper_fingertip_left" />
    <axis
      xyz="0 0 0" />
  </joint>
</robot>